Workbook
Name Circ: 'LBO Model'!$K$13
Name Floor: 'LBO Model'!$G$10
Name OpPay: 'LBO Model'!$G$11

Sheet Read Me First
B1: Read Me First | Fall 2026 LBO Model
B2: Student instructions, editable inputs, and model checks
B4: START HERE | E4: EDITING CONVENTIONS
B5: A leveraged buyout (LBO) is the purchase of a company using borrowed money and investor equity. This workbook is a starting template, not a completed company analysis. Replace the sample company data with verified history and supported forecasts. Do not invent missing information. Dollar amounts and share counts are in millions, except per-share prices. The calculations and input cells are on the LBO Model tab. | E5: Blue text + yellow fill = an editable input. Support your company and deal assumptions with evidence. Black calculation cells = formulas. Do not type over them. The gray SOFR cells are fixed assumptions, not student inputs. A dash in a number cell can mean zero; check the formula bar. A passing calculation check does not verify your sources or investment recommendation.
B12: FISCAL-YEAR SETUP | E12: CASH-TAX CONVENTION
B13: Start with the company's latest completed fiscal year, meaning the year covered by its most recent full-year results. Enter that year in K11, then its year-end month and day in K14/K15. Cell references in this guide are on LBO Model. The model shows three historical years (A = Actual) and five forecast years (E = Expected). The sample dates are examples, not a requirement to treat 2026 as reported. The provided three-month SOFR curve is fixed. Keep these rates in their existing forecast columns, even if you adjust the fiscal-year dates. | E13: Cash taxes are the taxes paid in the forecast. When pretax income is positive, the model applies the combined tax rate in G16, which adds the state and federal rates in G14/G15. A loss year produces zero cash tax, not an assumed cash refund. The model does not track losses that might reduce taxes in later years, called net operating losses (NOLs). Taxes affect the cash available for debt repayment and, ultimately, the investors' return. Use this simplified treatment consistently.
B22: CASH, DEBT REPAYMENT, AND CALCULATION | E22: SOFR, OID, AND DEBT PRICING
B23: Debt balances: column F shows debt at closing; G:K shows each forecast year-end. Interest uses the average of beginning and ending debt. Optional repayment: G11 sets the share of current-year excess cash used to repay debt early. It defaults to 0%. The model applies it once, paying the revolver first, then the first-lien loan. Notes receive no optional repayment. A revolver is a credit line. New borrowing can cover a cash shortfall only up to the unused credit limit. Borrowed cash is not swept into optional repayment. Retained cash flow (row 135) stays in company cash; it is not paid to investors during the holding period. At exit, remaining debt is deducted and retained cash is added when calculating the investors' proceeds. Interest and debt depend on each other, so Excel must use iterative calculation. Leave K13 at 1 for normal use; see the calculation instructions below. | E23: First-lien loan: the sample uses a seven-year term, SOFR + 3.75%, 1% OID, and annual principal repayments of 1% of the original loan. S + 375 means SOFR plus 375 basis points; 100 basis points equals 1 percentage point. G10 sets the SOFR floor, initially 0%. OID is an issue discount: 1% means receiving $99 for every $100 borrowed. It is not a principal repayment. The model spreads OID and upfront fees over the debt term. Tenor means years to maturity; the model does not automatically repay the full loan when that term ends. Fees: G9 is the annual fee on unused revolver capacity. J25:J27 are separate one-time fees at closing. Senior Unsecured Notes are optional debt, not required financing. The sample is $355 million for eight years at 7.5% fixed interest, with zero OID and no required annual or optional repayment. Support material changes to financing inputs with dated evidence.
B33: FIXED SOFR CURVE AND REQUIRED MODEL CHECKS
B34: The supplied SOFR curve. SOFR is an interest-rate benchmark used to price the floating-rate loans. The six gray cells in F69:K69 provide the model's three-month SOFR assumptions as of August 13, 2026. They are fixed for the competition, not inputs for students to research or update. For each forecast year, the model averages the adjacent year-end rates, applies the SOFR floor, and adds the loan's spread. Keep these rates in their existing forecast columns, even if you adjust the fiscal-year dates. Calculation settings. Use Automatic calculation, with iterative calculation enabled: 1,000 maximum iterations and 0.000001 maximum change. If a formula fails, set K13 to 0, correct the cause, then restore K13 to 1 and recalculate. K13 does not turn on Excel's calculation settings. Required results. The Sources and Uses check (E38) must show YES; G201:G216 and G220:G226 must show OK; Calculation Integrity (G217) must show PASS. Review cash, debt, minimum cash, revolver capacity, repayments, OID, interest, taxes, returns and dates. The lower illustrative checks do not replace testing your own assumptions. Decision Readiness (G218) stays at NEEDS INPUT. It is a reminder to review your company data, evidence and final memo, not a test that turns to PASS when you finish. You must complete that review yourself.
B46: ACRONYM GLOSSARY
B47: LBO: Leveraged buyout, a purchase financed with debt and investor equity. EV: Enterprise value, the value of the business before allocating value to debt and equity. EBITDA: Earnings before interest, taxes, depreciation and amortization. FCF: Free cash flow. Follow the row label to distinguish cash before and after debt repayments. D&A: Depreciation and amortization, expenses that allocate asset costs over time. SG&A: Selling, general and administrative expenses, such as sales and office costs. CapEx: Capital expenditures, spending on long-lived assets such as equipment. OID: Original issue discount, the difference between debt face value and its issue proceeds. NOL: Net operating loss, a tax loss that may reduce taxable income in a later year. SOFR / S: Secured Overnight Financing Rate. S denotes SOFR in the loan-pricing cells. A / E: Actual historical results / Expected forecast results. x: Times, used for valuation and investment-return multiples. N/A: Not available; the model cannot calculate a meaningful return from the inputs.
B58: FINAL CHECKLIST
B59: 1. Company data: Replace sample inputs with verified history and supported forecasts. Use credible, dated evidence and explain material deal-assumption changes. 2. Dates and financing: Check K11 and K14/K15. Keep the fixed SOFR rates in their existing forecast columns. Review debt amounts, spreads, fees, OID, principal repayments and the applicable competition requirements. 3. Model checks: Obtain YES, OK and PASS in the locations listed above. Separately complete the company-data and source review; the NEEDS INPUT reminder will remain. 4. Final memo: Make purchase price, financing, free cash flow, ending debt and cash, multiple on invested capital, and internal rate of return agree with the final model.
B68: TECHNOLOGY AND VALUE CREATION (OPTIONAL)
B69: New this year, an optional technology component invites you to consider how your target company could become more valuable after an acquisition. You might explore how technology could improve its products or services, create revenue opportunities, increase productivity, or strengthen margins. Make sure to connect the idea to the company's business and credible evidence. If you include this component, describe how the company currently uses technology, the opportunity you see, and the realistic benefits, costs and timing of your proposal. Limited public disclosure does not necessarily mean the company has a technology gap. You may discuss your idea qualitatively without changing the model. If you can support estimates of benefits and costs, include them in the relevant forecast assumptions without counting anything already included a second time. The optional fourth flash memo slide provides space for your proposal.

Sheet LBO Model
A1: JBT Marel Corporation | 6% Base Case LBO | G1: Calculation Integrity | I1: =G217 -> PASS
A2: USD millions; 2023–25 history, FY26 close baseline, five-year sponsor hold (2027–31). See Revenue Build and Value Creation & AI tabs for assumptions and scenarios. | C2: ="" | D2: =$K$11-2 -> 2023 | E2: =D2+1 -> 2024 | F2: =E2+1 -> 2025 | G2: =F2+2 -> 2027 | H2: =G2+1 -> 2028 | I2: =H2+1 -> 2029 | J2: =I2+1 -> 2030 | K2: =J2+1 -> 2031
A3: 6% Base Case | FY2027–FY2031 forecast | 5-year hold | C3: ="" | D3: =IF(D$2<=$K$11,"A","E") -> A | E3: =IF(E$2<=$K$11,"A","E") -> A | F3: =IF(F$2<=$K$11,"A","E") -> A | G3: =IF(G$2<=$K$11,"A","E") -> E | H3: =IF(H$2<=$K$11,"A","E") -> E | I3: =IF(I$2<=$K$11,"A","E") -> E | J3: =IF(J$2<=$K$11,"A","E") -> E | K3: =IF(K$2<=$K$11,"A","E") -> E
B5: Transaction Assumptions
B7: Purchase Price | E7: Structuring | I7: Sponsor Exit
B8: Company Name | C8: JBT Marel Corporation | E8: Revolver Capacity | G8: 300 | I8: Exit Year | K8: =K$2 -> 2031
B9: Ticker Symbol | C9: JBTM | E9: Revolver Unused Fee | G9: 0.01 | I9: EBITDA Multiple | K9: =C20 -> 12.951877
B10: Current Stock Price | C10: 110.05 | E10: SOFR Floor | G10: 0 | I10: Exit Fees | K10: 0.03
B11: Premium Paid | C11: 0.2 | E11: Optional Prepayment (0 - 100%) | G11: 1 | I11: Last Completed Fiscal Year | K11: 2025
B12: Offer Price per Share | C12: =C10*(1+C11) -> 132.06 | I12: Switches
B13: Diluted Shares Outstanding | C13: 51.876817 | E13: Other | I13: ="Controlled Circularity "&IF(K13=1,"On","Off") -> Controlled Circularity On | K13: 1
B14: Total Equity Value | C14: =C12*C13 -> 6850.8525 | E14: State Tax Rate | G14: 0.04 | I14: Fiscal Year-End Month | K14: 12
B15: Plus: Existing Debt | C15: 1679 | E15: Federal Tax Rate | G15: 0.21 | I15: Fiscal Year-End Day | K15: 31
B16: Plus: Minority Interest | C16: 0 | E16: Corporate Tax Rate | G16: 0.25
B17: Less: Cash Balance | C17: -93 | E17: Minimum Cash Balance | G17: 50
B18: Total Enterprise Value | C18: =SUM(C14:C17) -> 8436.8525
B19: LTM adjusted EBITDA (Jun-26) | C19: 651.4
B20: Purchase Multiple (EV / EBITDA) | C20: =C18/C19 -> 12.951877
B22: Sources & Uses
B24: Sources of Funds | C24: Amount ($) | D24: x EBITDA | E24: Amortization | F24: Tenor | G24: Rate | H24: OID Input (%) | I24: OID ($) | J24: Fees (%) | K24: Fees ($)
B25: =+"New Revolving Credit Facility ($"&G8&")" -> New Revolving Credit Facility ($300) | C25: 0 | D25: =+C25/$C$19 -> 0 | E25: 0 | F25: 5 | G25: 350 | H25: 0 | I25: =+$C25*H25 -> 0 | J25: 0.0125 | K25: =+$G8*J25 -> 3.75
B26: New First Lien Term Loan | C26: =$C$19*4.5 -> 2931.3 | D26: =+C26/$C$19 -> 4.5 | E26: 0.01 | F26: 7 | G26: 375 | H26: 0.01 | I26: =+$C26*H26 -> 29.313 | J26: 0.0225 | K26: =+$C26*J26 -> 65.95425
B27: New Senior Unsecured Notes | C27: 355 | D27: =+C27/$C$19 -> 0.54498004 | E27: 0 | F27: 8 | G27: 0.075 | H27: 0 | I27: =+$C27*H27 -> 0 | J27: 0.03 | K27: =+$C27*J27 -> 10.65
B28: Cash from Balance Sheet | C28: =+C17*-1 -> 93 | D28: =+C28/$C$19 -> 0.14276942
B29: New Sponsor Equity | C29: =+C38-SUM(C25:C28) -> 5394.5882 | D29: =+C29/$C$19 -> 8.2815294
B30: Total Sources of Funds | C30: =+SUM(C25:C29) -> 8773.8882 | D30: =+SUM(D25:D29) -> 13.469279 | I30: =+SUM(I25:I29) -> 29.313 | K30: =+SUM(K25:K29) -> 80.35425
B32: Uses of Funds | C32: Amount ($) | D32: x EBITDA
B33: Purchase Price of Equity | C33: =+C14 -> 6850.8525 | D33: =+C33/$C$19 -> 10.517121
B34: Refinance Existing Debt | C34: =+SUM(C15:C16) -> 1679 | D34: =+C34/$C$19 -> 2.5775253
B35: Cash to Balance Sheet | C35: =+G17 -> 50 | D35: =+C35/$C$19 -> 0.076757753
B36: Other One-Time Transaction Costs | C36: =$C$18*1% -> 84.368525 | D36: =+C36/$C$19 -> 0.12951877
B37: Estimated Fees & Expenses | C37: =+SUM(I30,K30) -> 109.66725 | D37: =+C37/$C$19 -> 0.16835623 | E37: Check
B38: Total Uses of Funds | C38: =+SUM(C33:C37) -> 8773.8882 | D38: =+SUM(D33:D37) -> 13.469279 | E38: =IF(ABS(C38-C30)<=0.01,"YES","NO") -> YES
B40: Financial Statement Assumptions
B42: Income Statement
C44: ="" | D44: =D$2&D$3 -> 2023A | E44: =E$2&E$3 -> 2024A | F44: =F$2&F$3 -> 2025A | G44: =G$2&G$3 -> 2027E | H44: =H$2&H$3 -> 2028E | I44: =I$2&I$3 -> 2029E | J44: =J$2&J$3 -> 2030E | K44: =K$2&K$3 -> 2031E
B45: Protein Solutions growth | C45: ="" | D45: ="" | E45: =IFERROR(E89/D89-1,0) -> -0.013015456 | F45: =IFERROR(F89/E89-1,0) -> 0.088061878 | G45: 0.06 | H45: 0.06 | I45: 0.06 | J45: 0.06 | K45: 0.06
B46: Prepared F&B Solutions growth | C46: ="" | D46: ="" | E46: =IFERROR(E90/D90-1,0) -> -0.012976981 | F46: =IFERROR(F90/E90-1,0) -> 0.086241978 | G46: 0.06 | H46: 0.06 | I46: 0.06 | J46: 0.06 | K46: 0.06
B47: Other revenue growth | C47: ="" | D47: ="" | E47: =IFERROR(E91/D91-1,0) -> 0 | F47: =IFERROR(F91/E91-1,0) -> 0 | G47: 0 | H47: 0 | I47: 0 | J47: 0 | K47: 0
B48: Total Revenues - Growth Rate | C48: ="" | D48: ="" | E48: =IFERROR(E92/D92-1,0) -> -0.01299435 | F48: =IFERROR(F92/E92-1,0) -> 0.087063537 | G48: =G92/'Revenue Build'!E8-1 -> 0.06 | H48: =H92/G92-1 -> 0.06 | I48: =I92/H92-1 -> 0.06 | J48: =J92/I92-1 -> 0.06 | K48: =K92/J92-1 -> 0.06
...

Sheet Revenue Build
A1: JBT Marel Revenue Build | 6% Base Case
A2: 6% Base Case revenue build; 2026 estimate is close baseline; analyst growth and AI assumptions are identified below.
A4: Revenue by segment | B4: 2023A | C4: 2024A | D4: 2025A | E4: 2026E | F4: 2027E | G4: 2028E | H4: 2029E | I4: 2030E | J4: 2031E
A5: Protein Solutions | B5: 1598.1 | C5: 1577.3 | D5: 1716.2 | E5: 1939 | F5: ='LBO Model'!G89 -> 2055.34 | G5: ='LBO Model'!H89 -> 2178.6604 | H5: ='LBO Model'!I89 -> 2309.38 | I5: ='LBO Model'!J89 -> 2447.9428 | J5: ='LBO Model'!K89 -> 2594.8194
A6: Prepared Food & Beverage Solutions | B6: =B8-B5 -> 1941.9 | C6: =C8-C5 -> 1916.7 | D6: =D8-D5 -> 2082 | E6: 2088.5 | F6: ='LBO Model'!G90 -> 2213.81 | G6: ='LBO Model'!H90 -> 2346.6386 | H6: ='LBO Model'!I90 -> 2487.4369 | I6: ='LBO Model'!J90 -> 2636.6831 | J6: ='LBO Model'!K90 -> 2794.8841
A7: Other | B7: 0 | C7: 0 | D7: 0 | E7: 0 | F7: 0 | G7: 0 | H7: 0 | I7: 0 | J7: 0
A8: Total Revenue | B8: 3540 | C8: 3494 | D8: 3798.2 | E8: 4027.5 | F8: =SUM(F5:F7) -> 4269.15 | G8: =SUM(G5:G7) -> 4525.299 | H8: =SUM(H5:H7) -> 4796.8169 | I8: =SUM(I5:I7) -> 5084.626 | J8: =SUM(J5:J7) -> 5389.7035
A9: Revenue growth | B9: =0 -> 0 | C9: =C8/B8-1 -> -0.01299435 | D9: =D8/C8-1 -> 0.087063537 | E9: =E8/D8-1 -> 0.060370702 | F9: =F8/E8-1 -> 0.06 | G9: =G8/F8-1 -> 0.06 | H9: =H8/G8-1 -> 0.06 | I9: =I8/H8-1 -> 0.06 | J9: =J8/I8-1 -> 0.06
A11: 2025 reported segment mix | B11: Revenue | C11: Share of sales | D11: Recurring sales share
A12: Protein Solutions | B12: 1716.2 | C12: 0.45184561 | D12: 0.525
A13: Prepared Food & Beverage Solutions | B13: 2082 | C13: 0.54815439 | D13: 0.486
A14: Total recurring revenue | B14: 1912.5 | C14: 0.50352799
A16: Model assumptions
A17: Adjusted EBITDA margin | E17: 0.1725 | F17: 0.186 | G17: 0.201 | H17: 0.202 | I17: 0.2035 | J17: 0.205
A18: Revenue growth after FY26 | F18: 0.06 | G18: 0.06 | H18: 0.06 | I18: 0.06 | J18: 0.06
A20: Plain-English notes
A21: 2023–24 combined sales are standalone JBT + Marel pro forma amounts; they were not audited combined financial statements.
A22: 2023–24 segment split is an estimate using FY25 mix. FY25 segment revenue is reported. Other revenue is zero for simplicity.
A23: FY26 revenue is the midpoint of management’s $3,990–$4,065M guidance; segment split is an estimate consistent with 1H26 segment trends.
A24: 6% annual revenue growth is an analyst scenario; the 20% FY2028 EBITDA margin target is management guidance. AI margin benefit is an analyst assumption where applicable.
A25: Synergy savings are reflected in the EBITDA margin target and are not added a second time. See Value Creation & AI for management’s margin bridge, disclosed synergy schedule, and a separate AI upside case.
A26: LBO entry uses Sep. 25, 2026 stock price, June 30, 2026 debt/cash, July 24 shares, and LTM adjusted EBITDA through June 2026. Close assumed Dec. 31, 2026.
A27: Historical and projected operating statements are normalized to Adjusted EBITDA; they are not GAAP financial statements. Financing terms and a 12.95x exit multiple are illustrative.
A29: Source | B29: Use | C29: Link
A30: FY25 Form 10-K | B30: 2025 segment revenue, recurring revenue, adjusted EBITDA, CapEx, D&A | C30: https://www.sec.gov/Archives/edgar/data/1433660/000143366026000053/jbt-20251231.htm
A31: Q2 2026 Form 10-Q | B31: Shares, debt, cash, H1 segment revenue/EBITDA | C31: https://www.sec.gov/Archives/edgar/data/1433660/000162828026053548/jbt-20260630.htm
A32: Q2 2026 earnings release | B32: FY26 sales and EBITDA margin guidance | C32: https://www.sec.gov/Archives/edgar/data/1433660/000162828026051894/a2026q2earningsexhibit9918k.htm
A33: 2026 Investor Day | B33: 2028 5–7% organic sales growth / 20% adjusted EBITDA margin target; $150M savings run-rate target | C33: https://www.sec.gov/Archives/edgar/data/1433660/000143366026000071/exhibit991-jbtmarel2026i.htm
A34: 2024 earnings release | B34: 2024 combined standalone revenue and adjusted EBITDA | C34: https://www.sec.gov/Archives/edgar/data/1433660/000143366025000002/a2024q4earningsexhibit9918k.htm
A35: 2023 combination presentation | B35: 2023 JBT and Marel standalone revenue/EBITDA; combined proxy | C35: https://www.sec.gov/Archives/edgar/data/1433660/000119312524151787/d643713d425.htm
A36: JBTM historical share price | B36: Sep. 25, 2026 closing price of $110.05 | C36: https://chartexchange.com/symbol/nyse-jbtm/historical/
A37: SOFR curve | B37: Existing fixed competition template curve, retained unchanged | C37: Fall 2026 LBO Model Template.xlsx

Sheet Value Creation & AI
A1: JBT Marel Value Creation and Scenario Assumptions ($ millions)
A2: Company targets are separated from analyst assumptions. The AI case is an upside scenario, not management guidance.
A4: Management’s FY25–FY28 EBITDA margin bridge | B4: Low | C4: High | D4: Unit | E4: Meaning
A5: FY2025 adjusted EBITDA margin | B5: 0.158 | C5: 0.158 | D5: % | E5: Reported starting margin
A6: Growth / mix contribution | B6: 0.005 | C6: 0.0075 | D6: % points | E6: Management estimate
A7: Cost synergy contribution | B7: 0.0225 | C7: 0.025 | D7: % points | E7: Management estimate
A8: Continuous improvement | B8: 0.011 | C8: 0.013 | D8: % points | E8: Management estimate
A9: Implied FY2028 adjusted EBITDA margin | B9: =SUM(B5:B8) -> 0.1965 | C9: =SUM(C5:C8) -> 0.2035 | D9: % | E9: Range is rounded; company target is 20%
A10: FY2028 adjusted EBITDA margin target | B10: 0.2 | C10: 0.2 | D10: % | E10: Management target
A12: Disclosed cost synergy plan | B12: OPEX low | C12: OPEX high | D12: COGS low | E12: COGS high | F12: Total low | G12: Total high
A13: FY2025 actual | B13: 24 | C13: 24 | D13: 19 | E13: 19 | F13: =B13+D13 -> 43 | G13: =C13+E13 -> 43
A14: FY2026 estimate | B14: 20 | C14: 20 | D14: 40 | E14: 40 | F14: =B14+D14 -> 60 | G14: =C14+E14 -> 60
A15: FY2027 estimate | B15: 10 | C15: 15 | D15: 20 | E15: 25 | F15: =B15+D15 -> 30 | G15: =C15+E15 -> 40
A16: FY2028 estimate | B16: 5 | C16: 5 | D16: 5 | E16: 10 | F16: =B16+D16 -> 10 | G16: =C16+E16 -> 15
A17: Total in-year savings | B17: =SUM(B13:B16) -> 59 | C17: =SUM(C13:C16) -> 64 | D17: =SUM(D13:D16) -> 84 | E17: =SUM(E13:E16) -> 94 | F17: =SUM(F13:F16) -> 143 | G17: =SUM(G13:G16) -> 158
A19: Annual run-rate milestone | B19: Savings | C19: Timing | D19: How the LBO uses it
A20: Run-rate savings achieved | B20: 85 | C20: Exit FY2025 | D20: Part of the reported and forecast earnings base
A21: Run-rate savings target | B21: 150 | C21: Exit FY2027 | D21: Reflected in management’s margin plan; not added on top
A22: The base LBO already ramps adjusted EBITDA margin to management’s 20% FY2028 target. That target includes the savings plan and other margin actions; adding $150M again would double count. The in-year savings schedule above is copied from management’s Investor Day plan.
A24: Illustrative 6% Base Case: revenue growth and AI upside are analyst assumptions, not company guidance
A25: Assumption | B25: 5% Downside | C25: 6% Base Case | D25: Basis
A26: Annual revenue growth, 2027–2031 | B26: 0.05 | C26: 0.06 | D26: AI-enabled equipment wins, cross-sell, and service attachment; 6% is within management’s 5–7% 2025–28 outlook
A27: Incremental EBITDA margin from AI by 2031 | B27: 0 | C27: 0.005 | D27: Ramps to 0.50 percentage points by 2031 after product, service, and engineering costs
A28: Incremental FCF converted to debt paydown | C28: 0.7 | D28: Analyst estimate after tax, working capital, and capital spending
A30: Year | B30: Base revenue | C30: AI revenue growth | D30: AI revenue | E30: Base EBITDA margin | F30: AI margin uplift | G30: AI EBITDA | H30: Incremental EBITDA | I30: Incremental FCF to debt | J30: AI case term debt
A31: 2027 | B31: ='LBO Model'!G92 -> 4269.15 | C31: =$C$26 -> 0.06 | D31: ='Revenue Build'!E8*(1+C31) -> 4269.15 | E31: ='5% Downside - LBO Model'!G119 -> 0.186 | F31: 0 | G31: =D31*(E31+F31) -> 794.0619 | H31: =G31-'5% Downside - LBO Model'!G118 -> 7.49115 | I31: =MAX(0,H31*$C$28) -> 5.243805 | J31: ='LBO Model'!G157 -> 2547.8723
A32: 2028 | B32: ='LBO Model'!H92 -> 4525.299 | C32: =$C$26 -> 0.06 | D32: =D31*(1+C32) -> 4525.299 | E32: ='5% Downside - LBO Model'!H119 -> 0.2 | F32: 0.001 | G32: =D32*(E32+F32) -> 909.5851 | H32: =G32-'5% Downside - LBO Model'!H118 -> 21.521349 | I32: =MAX(0,H32*$C$28) -> 15.064944 | J32: ='LBO Model'!H157 -> 2043.0155
A33: 2029 | B33: ='LBO Model'!I92 -> 4796.8169 | C33: =$C$26 -> 0.06 | D33: =D32*(1+C33) -> 4796.8169 | E33: ='5% Downside - LBO Model'!I119 -> 0.2 | F33: 0.002 | G33: =D33*(E33+F33) -> 968.95702 | H33: =G33-'5% Downside - LBO Model'!I118 -> 36.490084 | I33: =MAX(0,H33*$C$28) -> 25.543059 | J33: ='LBO Model'!I157 -> 1466.7343
A34: 2030 | B34: ='LBO Model'!J92 -> 5084.626 | C34: =$C$26 -> 0.06 | D34: =D33*(1+C34) -> 5084.626 | E34: ='5% Downside - LBO Model'!J119 -> 0.2 | F34: 0.0035 | G34: =D34*(E34+F34) -> 1034.7214 | H34: =G34-'5% Downside - LBO Model'!J118 -> 55.631098 | I34: =MAX(0,H34*$C$28) -> 38.941768 | J34: ='LBO Model'!J157 -> 810.56482
A35: 2031 | B35: ='LBO Model'!K92 -> 5389.7035 | C35: =$C$26 -> 0.06 | D35: =D34*(1+C35) -> 5389.7035 | E35: ='5% Downside - LBO Model'!K119 -> 0.2 | F35: 0.005 | G35: =D35*(E35+F35) -> 1104.8892 | H35: =G35-'5% Downside - LBO Model'!K118 -> 76.844422 | I35: =MAX(0,H35*$C$28) -> 53.791095 | J35: ='LBO Model'!K157 -> 67.540609
A37: Return comparison | B37: 5% Downside | C37: 6% Base Case | D37: Notes
A38: 2031 revenue | B38: ='5% Downside - LBO Model'!K92 -> 5140.224 | C38: ='LBO Model'!K92 -> 5389.7035 | D38: AI scenario compounds 6% growth from the FY2026 guidance midpoint
A39: 2031 adjusted EBITDA | B39: ='5% Downside - LBO Model'!K118 -> 1028.0448 | C39: ='LBO Model'!K118 -> 1104.8892 | D39: Base margin target plus AI margin ramp
A40: Exit enterprise value | B40: ='5% Downside - LBO Model'!K184 -> 13315.109 | C40: ='LBO Model'!K184 -> 14310.389 | D40: 12.95x, same as entry
A41: Debt at exit | B41: =-'5% Downside - LBO Model'!K185 -> 1019.8322 | C41: =-'LBO Model'!K185 -> 422.54061 | D41: AI case uses 70% of incremental FCF to repay term debt
A42: Exit equity proceeds | B42: ='5% Downside - LBO Model'!K188 -> 11945.824 | C42: ='LBO Model'!K188 -> 13508.537 | D42: Includes $50M cash and 3% exit fees
A43: Multiple on invested capital | B43: ='5% Downside - LBO Model'!C196 -> 2.2144089 | C43: ='LBO Model'!C196 -> 2.5040904 | D43: Same sponsor investment
A44: Annualized IRR | B44: ='5% Downside - LBO Model'!C197 -> 0.17233454 | C44: ='LBO Model'!C197 -> 0.20151722 | D44: Five-year hold; no interim distributions
A46: The AI case assumes growth rises to 6% per year and AI supports a 0.50-point EBITDA margin benefit by 2031. JBT Marel has published machine-vision and machine-learning examples, but has not disclosed a company-wide AI revenue or EBITDA target; this scenario is a testable hypothesis, not a forecast.
A48: Evidence / source | B48: What it supports | C48: Link
...

Sheet 5% Downside - LBO Model
A1: JBT Marel Corporation | 5% Downside LBO | G1: Calculation Integrity | I1: =G217 -> PASS
A2: USD millions; 2023–25 history, FY26 close baseline, five-year sponsor hold (2027–31). See Revenue Build and Value Creation & AI tabs for assumptions and scenarios. | C2: ="" | D2: =$K$11-2 -> 2023 | E2: =D2+1 -> 2024 | F2: =E2+1 -> 2025 | G2: 2027 | H2: 2028 | I2: 2029 | J2: 2030 | K2: 2031
A3: 5% Downside Case | FY2027–FY2031 forecast | 5-year hold | C3: ="" | D3: =IF(D$2<=$K$11,"A","E") -> A | E3: A | F3: A | G3: E | H3: E | I3: E | J3: E | K3: E
B5: Transaction Assumptions
B7: Purchase Price | E7: Structuring | I7: Sponsor Exit
B8: Company Name | C8: JBT Marel Corporation | E8: Revolver Capacity | G8: 300 | I8: Exit Year | K8: =K$2 -> 2031
B9: Ticker Symbol | C9: JBTM | E9: Revolver Unused Fee | G9: 0.01 | I9: EBITDA Multiple | K9: =C20 -> 12.951877
B10: Current Stock Price | C10: 110.05 | E10: SOFR Floor | G10: 0 | I10: Exit Fees | K10: 0.03
B11: Premium Paid | C11: 0.2 | E11: Optional Prepayment (0 - 100%) | G11: 1 | I11: Last Completed Fiscal Year | K11: 2025
B12: Offer Price per Share | C12: =C10*(1+C11) -> 132.06 | I12: Switches
B13: Diluted Shares Outstanding | C13: 51.876817 | E13: Other | I13: ="Controlled Circularity "&IF(K13=1,"On","Off") -> Controlled Circularity On | K13: 1
B14: Total Equity Value | C14: =C12*C13 -> 6850.8525 | E14: State Tax Rate | G14: 0.04 | I14: Fiscal Year-End Month | K14: 12
B15: Plus: Existing Debt | C15: 1679 | E15: Federal Tax Rate | G15: 0.21 | I15: Fiscal Year-End Day | K15: 31
B16: Plus: Minority Interest | C16: 0 | E16: Corporate Tax Rate | G16: 0.25
B17: Less: Cash Balance | C17: -93 | E17: Minimum Cash Balance | G17: 50
B18: Total Enterprise Value | C18: =SUM(C14:C17) -> 8436.8525
B19: LTM adjusted EBITDA (Jun-26) | C19: 651.4
B20: Purchase Multiple (EV / EBITDA) | C20: =C18/C19 -> 12.951877
B22: Sources & Uses
B24: Sources of Funds | C24: Amount ($) | D24: x EBITDA | E24: Amortization | F24: Tenor | G24: Rate | H24: OID Input (%) | I24: OID ($) | J24: Fees (%) | K24: Fees ($)
B25: =+"New Revolving Credit Facility ($"&G8&")" -> New Revolving Credit Facility ($300) | C25: 0 | D25: =+C25/$C$19 -> 0 | E25: 0 | F25: 5 | G25: 350 | H25: 0 | I25: =+$C25*H25 -> 0 | J25: 0.0125 | K25: =+$G8*J25 -> 3.75
B26: New First Lien Term Loan | C26: =$C$19*4.5 -> 2931.3 | D26: =+C26/$C$19 -> 4.5 | E26: 0.01 | F26: 7 | G26: 375 | H26: 0.01 | I26: =+$C26*H26 -> 29.313 | J26: 0.0225 | K26: =+$C26*J26 -> 65.95425
B27: New Senior Unsecured Notes | C27: 355 | D27: =+C27/$C$19 -> 0.54498004 | E27: 0 | F27: 8 | G27: 0.075 | H27: 0 | I27: =+$C27*H27 -> 0 | J27: 0.03 | K27: =+$C27*J27 -> 10.65
B28: Cash from Balance Sheet | C28: =+C17*-1 -> 93 | D28: =+C28/$C$19 -> 0.14276942
B29: New Sponsor Equity | C29: =+C38-SUM(C25:C28) -> 5394.5882 | D29: =+C29/$C$19 -> 8.2815294
B30: Total Sources of Funds | C30: =+SUM(C25:C29) -> 8773.8882 | D30: =+SUM(D25:D29) -> 13.469279 | I30: =+SUM(I25:I29) -> 29.313 | K30: =+SUM(K25:K29) -> 80.35425
B32: Uses of Funds | C32: Amount ($) | D32: x EBITDA
B33: Purchase Price of Equity | C33: =+C14 -> 6850.8525 | D33: =+C33/$C$19 -> 10.517121
B34: Refinance Existing Debt | C34: =+SUM(C15:C16) -> 1679 | D34: =+C34/$C$19 -> 2.5775253
B35: Cash to Balance Sheet | C35: =+G17 -> 50 | D35: =+C35/$C$19 -> 0.076757753
B36: Other One-Time Transaction Costs | C36: =$C$18*1% -> 84.368525 | D36: =+C36/$C$19 -> 0.12951877
B37: Estimated Fees & Expenses | C37: =+SUM(I30,K30) -> 109.66725 | D37: =+C37/$C$19 -> 0.16835623 | E37: Check
B38: Total Uses of Funds | C38: =+SUM(C33:C37) -> 8773.8882 | D38: =+SUM(D33:D37) -> 13.469279 | E38: =IF(ABS(C38-C30)<=0.01,"YES","NO") -> YES
B40: Financial Statement Assumptions
B42: Income Statement
C44: ="" | D44: =D$2&D$3 -> 2023A | E44: =E$2&E$3 -> 2024A | F44: =F$2&F$3 -> 2025A | G44: =G$2&G$3 -> 2027E | H44: =H$2&H$3 -> 2028E | I44: =I$2&I$3 -> 2029E | J44: =J$2&J$3 -> 2030E | K44: =K$2&K$3 -> 2031E
B45: Protein Solutions growth | C45: ="" | D45: ="" | E45: =IFERROR(E89/D89-1,0) -> -0.013015456 | F45: 0.038961039 | G45: 0.05 | H45: 0.05 | I45: 0.05 | J45: 0.05 | K45: 0.05
B46: Prepared F&B Solutions growth | C46: ="" | D46: ="" | E46: 0.046195652 | F46: 0.038961039 | G46: 0.05 | H46: 0.05 | I46: 0.05 | J46: 0.05 | K46: 0.05
B47: Other revenue growth | C47: ="" | D47: ="" | E47: 0.046195652 | F47: 0.038961039 | G47: 0 | H47: 0 | I47: 0 | J47: 0 | K47: 0
B48: Total Revenues - Growth Rate | C48: ="" | D48: ="" | E48: 0.046195652 | F48: 0.038961039 | G48: =G92/'5% Downside - Revenue Build'!E8-1 -> 0.05 | H48: =H92/G92-1 -> 0.05 | I48: =I92/H92-1 -> 0.05 | J48: =J92/I92-1 -> 0.05 | K48: =K92/J92-1 -> 0.05
...

Sheet 5% Downside - Revenue Build
A1: JBT Marel Revenue Build | 5% Downside
A2: Reported and illustrative revenue history; the 2026 estimate is the LBO close baseline.
A4: Revenue by segment | B4: 2023A | C4: 2024A | D4: 2025A | E4: 2026E | F4: 2027E | G4: 2028E | H4: 2029E | I4: 2030E | J4: 2031E
A5: Protein Solutions | B5: 1598.1 | C5: 1577.3 | D5: 1716.2 | E5: 1939 | F5: ='5% Downside - LBO Model'!G89 -> 2035.95 | G5: ='5% Downside - LBO Model'!H89 -> 2137.7475 | H5: ='5% Downside - LBO Model'!I89 -> 2244.6349 | I5: ='5% Downside - LBO Model'!J89 -> 2356.8666 | J5: ='5% Downside - LBO Model'!K89 -> 2474.7099
A6: Prepared Food & Beverage Solutions | B6: =B8-B5 -> 1941.9 | C6: =C8-C5 -> 1916.7 | D6: =D8-D5 -> 2082 | E6: 2088.5 | F6: ='5% Downside - LBO Model'!G90 -> 2192.925 | G6: ='5% Downside - LBO Model'!H90 -> 2302.5713 | H6: ='5% Downside - LBO Model'!I90 -> 2417.6998 | I6: ='5% Downside - LBO Model'!J90 -> 2538.5848 | J6: ='5% Downside - LBO Model'!K90 -> 2665.514
A7: Other | B7: 0 | C7: 0 | D7: 0 | E7: 0 | F7: 0 | G7: 0 | H7: 0 | I7: 0 | J7: 0
A8: Total Revenue | B8: 3540 | C8: 3494 | D8: 3798.2 | E8: 4027.5 | F8: =SUM(F5:F7) -> 4228.875 | G8: =SUM(G5:G7) -> 4440.3188 | H8: =SUM(H5:H7) -> 4662.3347 | I8: =SUM(I5:I7) -> 4895.4514 | J8: =SUM(J5:J7) -> 5140.224
A9: Revenue growth | B9: =0 -> 0 | C9: =C8/B8-1 -> -0.01299435 | D9: =D8/C8-1 -> 0.087063537 | E9: =E8/D8-1 -> 0.060370702 | F9: =F8/E8-1 -> 0.05 | G9: =G8/F8-1 -> 0.05 | H9: =H8/G8-1 -> 0.05 | I9: =I8/H8-1 -> 0.05 | J9: =J8/I8-1 -> 0.05
A11: 2025 reported segment mix | B11: Revenue | C11: Share of sales | D11: Recurring sales share
A12: Protein Solutions | B12: 1716.2 | C12: 0.45184561 | D12: 0.525
A13: Prepared Food & Beverage Solutions | B13: 2082 | C13: 0.54815439 | D13: 0.486
A14: Total recurring revenue | B14: 1912.5 | C14: 0.50352799
A16: Model assumptions
A17: Adjusted EBITDA margin | E17: 0.1725 | F17: 0.186 | G17: 0.2 | H17: 0.2 | I17: 0.2 | J17: 0.2
A18: Revenue growth after FY26 | F18: 0.05 | G18: 0.05 | H18: 0.05 | I18: 0.05 | J18: 0.05
A20: Plain-English notes
A21: 2023–24 combined sales are standalone JBT + Marel pro forma amounts; they were not audited combined financial statements.
A22: 2023–24 segment split is an estimate using FY25 mix. FY25 segment revenue is reported. Other revenue is zero for simplicity.
A23: FY26 revenue is the midpoint of management’s $3,990–$4,065M guidance; segment split is an estimate consistent with 1H26 segment trends.
A24: 5% annual revenue growth is an analyst scenario; the 20% FY2028 EBITDA margin target is management guidance. AI margin benefit is an analyst assumption where applicable.
A25: Synergy savings are reflected in the EBITDA margin target and are not added a second time. See Value Creation & AI for management’s margin bridge, disclosed synergy schedule, and a separate AI upside case.
A26: LBO entry uses Sep. 25, 2026 stock price, June 30, 2026 debt/cash, July 24 shares, and LTM adjusted EBITDA through June 2026. Close assumed Dec. 31, 2026.
A27: Historical and projected operating statements are normalized to Adjusted EBITDA; they are not GAAP financial statements. Financing terms and a 12.95x exit multiple are illustrative.

Sheet 7% Stretch - LBO Model
A1: JBT Marel Corporation | 7% Stretch LBO | G1: Calculation Integrity | I1: =G217 -> PASS
A2: USD millions; 2023–25 history, FY26 close baseline, five-year sponsor hold (2027–31). See Revenue Build and Value Creation & AI tabs for assumptions and scenarios. | C2: ="" | D2: =$K$11-2 -> 2023 | E2: =D2+1 -> 2024 | F2: =E2+1 -> 2025 | G2: 2027 | H2: 2028 | I2: 2029 | J2: 2030 | K2: 2031
A3: 7% Stretch Case | FY2027–FY2031 forecast | 5-year hold | C3: ="" | D3: =IF(D$2<=$K$11,"A","E") -> A | E3: A | F3: A | G3: E | H3: E | I3: E | J3: E | K3: E
B5: Transaction Assumptions
B7: Purchase Price | E7: Structuring | I7: Sponsor Exit
B8: Company Name | C8: JBT Marel Corporation | E8: Revolver Capacity | G8: 300 | I8: Exit Year | K8: =K$2 -> 2031
B9: Ticker Symbol | C9: JBTM | E9: Revolver Unused Fee | G9: 0.01 | I9: EBITDA Multiple | K9: =C20 -> 12.951877
B10: Current Stock Price | C10: 110.05 | E10: SOFR Floor | G10: 0 | I10: Exit Fees | K10: 0.03
B11: Premium Paid | C11: 0.2 | E11: Optional Prepayment (0 - 100%) | G11: 1 | I11: Last Completed Fiscal Year | K11: 2025
B12: Offer Price per Share | C12: =C10*(1+C11) -> 132.06 | I12: Switches
B13: Diluted Shares Outstanding | C13: 51.876817 | E13: Other | I13: ="Controlled Circularity "&IF(K13=1,"On","Off") -> Controlled Circularity On | K13: 1
B14: Total Equity Value | C14: =C12*C13 -> 6850.8525 | E14: State Tax Rate | G14: 0.04 | I14: Fiscal Year-End Month | K14: 12
B15: Plus: Existing Debt | C15: 1679 | E15: Federal Tax Rate | G15: 0.21 | I15: Fiscal Year-End Day | K15: 31
B16: Plus: Minority Interest | C16: 0 | E16: Corporate Tax Rate | G16: 0.25
B17: Less: Cash Balance | C17: -93 | E17: Minimum Cash Balance | G17: 50
B18: Total Enterprise Value | C18: =SUM(C14:C17) -> 8436.8525
B19: LTM adjusted EBITDA (Jun-26) | C19: 651.4
B20: Purchase Multiple (EV / EBITDA) | C20: =C18/C19 -> 12.951877
B22: Sources & Uses
B24: Sources of Funds | C24: Amount ($) | D24: x EBITDA | E24: Amortization | F24: Tenor | G24: Rate | H24: OID Input (%) | I24: OID ($) | J24: Fees (%) | K24: Fees ($)
B25: =+"New Revolving Credit Facility ($"&G8&")" -> New Revolving Credit Facility ($300) | C25: 0 | D25: =+C25/$C$19 -> 0 | E25: 0 | F25: 5 | G25: 350 | H25: 0 | I25: =+$C25*H25 -> 0 | J25: 0.0125 | K25: =+$G8*J25 -> 3.75
B26: New First Lien Term Loan | C26: =$C$19*4.5 -> 2931.3 | D26: =+C26/$C$19 -> 4.5 | E26: 0.01 | F26: 7 | G26: 375 | H26: 0.01 | I26: =+$C26*H26 -> 29.313 | J26: 0.0225 | K26: =+$C26*J26 -> 65.95425
B27: New Senior Unsecured Notes | C27: 355 | D27: =+C27/$C$19 -> 0.54498004 | E27: 0 | F27: 8 | G27: 0.075 | H27: 0 | I27: =+$C27*H27 -> 0 | J27: 0.03 | K27: =+$C27*J27 -> 10.65
B28: Cash from Balance Sheet | C28: =+C17*-1 -> 93 | D28: =+C28/$C$19 -> 0.14276942
B29: New Sponsor Equity | C29: =+C38-SUM(C25:C28) -> 5394.5882 | D29: =+C29/$C$19 -> 8.2815294
B30: Total Sources of Funds | C30: =+SUM(C25:C29) -> 8773.8882 | D30: =+SUM(D25:D29) -> 13.469279 | I30: =+SUM(I25:I29) -> 29.313 | K30: =+SUM(K25:K29) -> 80.35425
B32: Uses of Funds | C32: Amount ($) | D32: x EBITDA
B33: Purchase Price of Equity | C33: =+C14 -> 6850.8525 | D33: =+C33/$C$19 -> 10.517121
B34: Refinance Existing Debt | C34: =+SUM(C15:C16) -> 1679 | D34: =+C34/$C$19 -> 2.5775253
B35: Cash to Balance Sheet | C35: =+G17 -> 50 | D35: =+C35/$C$19 -> 0.076757753
B36: Other One-Time Transaction Costs | C36: =$C$18*1% -> 84.368525 | D36: =+C36/$C$19 -> 0.12951877
B37: Estimated Fees & Expenses | C37: =+SUM(I30,K30) -> 109.66725 | D37: =+C37/$C$19 -> 0.16835623 | E37: Check
B38: Total Uses of Funds | C38: =+SUM(C33:C37) -> 8773.8882 | D38: =+SUM(D33:D37) -> 13.469279 | E38: =IF(ABS(C38-C30)<=0.01,"YES","NO") -> YES
B40: Financial Statement Assumptions
B42: Income Statement
C44: ="" | D44: =D$2&D$3 -> 2023A | E44: =E$2&E$3 -> 2024A | F44: =F$2&F$3 -> 2025A | G44: =G$2&G$3 -> 2027E | H44: =H$2&H$3 -> 2028E | I44: =I$2&I$3 -> 2029E | J44: =J$2&J$3 -> 2030E | K44: =K$2&K$3 -> 2031E
B45: Protein Solutions growth | C45: ="" | D45: ="" | E45: =IFERROR(E89/D89-1,0) -> -0.013015456 | F45: 0.038961039 | G45: 0.07 | H45: 0.07 | I45: 0.07 | J45: 0.07 | K45: 0.07
B46: Prepared F&B Solutions growth | C46: ="" | D46: ="" | E46: 0.046195652 | F46: 0.038961039 | G46: 0.07 | H46: 0.07 | I46: 0.07 | J46: 0.07 | K46: 0.07
B47: Other revenue growth | C47: ="" | D47: ="" | E47: 0.046195652 | F47: 0.038961039 | G47: 0 | H47: 0 | I47: 0 | J47: 0 | K47: 0
B48: Total Revenues - Growth Rate | C48: ="" | D48: ="" | E48: 0.046195652 | F48: 0.038961039 | G48: =G92/'7% Stretch - Revenue Build'!E8-1 -> 0.07 | H48: =H92/G92-1 -> 0.07 | I48: =I92/H92-1 -> 0.07 | J48: =J92/I92-1 -> 0.07 | K48: =K92/J92-1 -> 0.07
...

Sheet 7% Stretch - Revenue Build
A1: JBT Marel Revenue Build | 7% Stretch
A2: Reported and illustrative revenue history; the 2026 estimate is the LBO close baseline.
A4: Revenue by segment | B4: 2023A | C4: 2024A | D4: 2025A | E4: 2026E | F4: 2027E | G4: 2028E | H4: 2029E | I4: 2030E | J4: 2031E
A5: Protein Solutions | B5: 1598.1 | C5: 1577.3 | D5: 1716.2 | E5: 1939 | F5: ='7% Stretch - LBO Model'!G89 -> 2074.73 | G5: ='7% Stretch - LBO Model'!H89 -> 2219.9611 | H5: ='7% Stretch - LBO Model'!I89 -> 2375.3584 | I5: ='7% Stretch - LBO Model'!J89 -> 2541.6335 | J5: ='7% Stretch - LBO Model'!K89 -> 2719.5478
A6: Prepared Food & Beverage Solutions | B6: =B8-B5 -> 1941.9 | C6: =C8-C5 -> 1916.7 | D6: =D8-D5 -> 2082 | E6: 2088.5 | F6: ='7% Stretch - LBO Model'!G90 -> 2234.695 | G6: ='7% Stretch - LBO Model'!H90 -> 2391.1237 | H6: ='7% Stretch - LBO Model'!I90 -> 2558.5023 | I6: ='7% Stretch - LBO Model'!J90 -> 2737.5975 | J6: ='7% Stretch - LBO Model'!K90 -> 2929.2293
A7: Other | B7: 0 | C7: 0 | D7: 0 | E7: 0 | F7: 0 | G7: 0 | H7: 0 | I7: 0 | J7: 0
A8: Total Revenue | B8: 3540 | C8: 3494 | D8: 3798.2 | E8: 4027.5 | F8: =SUM(F5:F7) -> 4309.425 | G8: =SUM(G5:G7) -> 4611.0847 | H8: =SUM(H5:H7) -> 4933.8607 | I8: =SUM(I5:I7) -> 5279.2309 | J8: =SUM(J5:J7) -> 5648.7771
A9: Revenue growth | B9: =0 -> 0 | C9: =C8/B8-1 -> -0.01299435 | D9: =D8/C8-1 -> 0.087063537 | E9: =E8/D8-1 -> 0.060370702 | F9: =F8/E8-1 -> 0.07 | G9: =G8/F8-1 -> 0.07 | H9: =H8/G8-1 -> 0.07 | I9: =I8/H8-1 -> 0.07 | J9: =J8/I8-1 -> 0.07
A11: 2025 reported segment mix | B11: Revenue | C11: Share of sales | D11: Recurring sales share
A12: Protein Solutions | B12: 1716.2 | C12: 0.45184561 | D12: 0.525
A13: Prepared Food & Beverage Solutions | B13: 2082 | C13: 0.54815439 | D13: 0.486
A14: Total recurring revenue | B14: 1912.5 | C14: 0.50352799
A16: Model assumptions
A17: Adjusted EBITDA margin | E17: 0.1725 | F17: 0.186 | G17: 0.202 | H17: 0.204 | I17: 0.207 | J17: 0.21
A18: Revenue growth after FY26 | F18: 0.07 | G18: 0.07 | H18: 0.07 | I18: 0.07 | J18: 0.07
A20: Plain-English notes
A21: 2023–24 combined sales are standalone JBT + Marel pro forma amounts; they were not audited combined financial statements.
A22: 2023–24 segment split is an estimate using FY25 mix. FY25 segment revenue is reported. Other revenue is zero for simplicity.
A23: FY26 revenue is the midpoint of management’s $3,990–$4,065M guidance; segment split is an estimate consistent with 1H26 segment trends.
A24: 7% annual revenue growth is an analyst scenario; the 20% FY2028 EBITDA margin target is management guidance. AI margin benefit is an analyst assumption where applicable.
A25: Synergy savings are reflected in the EBITDA margin target and are not added a second time. See Value Creation & AI for management’s margin bridge, disclosed synergy schedule, and a separate AI upside case.
A26: LBO entry uses Sep. 25, 2026 stock price, June 30, 2026 debt/cash, July 24 shares, and LTM adjusted EBITDA through June 2026. Close assumed Dec. 31, 2026.
A27: Historical and projected operating statements are normalized to Adjusted EBITDA; they are not GAAP financial statements. Financing terms and a 12.95x exit multiple are illustrative.

Sheet Return Sensitivity
A1: JBT Marel Return Sensitivity
A2: MOIC and IRR at alternative exit EV / EBITDA multiples; each case uses its own modeled EBITDA, debt, cash, and sponsor equity.
A4: MOIC Sensitivity | B4: 11 | C4: 12 | D4: 12.951877 | E4: 13.5 | F4: 14
A5: 5% Downside | B5: =('5% Downside - LBO Model'!$K$118*B$4*(1-'5% Downside - LBO Model'!$K$10)-'5% Downside - LBO Model'!$K$159+'5% Downside - LBO Model'!$K$142)/-'5% Downside - LBO Model'!$F$191 -> 1.8535995 | C5: =('5% Downside - LBO Model'!$K$118*C$4*(1-'5% Downside - LBO Model'!$K$10)-'5% Downside - LBO Model'!$K$159+'5% Downside - LBO Model'!$K$142)/-'5% Downside - LBO Model'!$F$191 -> 2.038452 | D5: =('5% Downside - LBO Model'!$K$118*D$4*(1-'5% Downside - LBO Model'!$K$10)-'5% Downside - LBO Model'!$K$159+'5% Downside - LBO Model'!$K$142)/-'5% Downside - LBO Model'!$F$191 -> 2.2144089 | E5: =('5% Downside - LBO Model'!$K$118*E$4*(1-'5% Downside - LBO Model'!$K$10)-'5% Downside - LBO Model'!$K$159+'5% Downside - LBO Model'!$K$142)/-'5% Downside - LBO Model'!$F$191 -> 2.3157309 | F5: =('5% Downside - LBO Model'!$K$118*F$4*(1-'5% Downside - LBO Model'!$K$10)-'5% Downside - LBO Model'!$K$159+'5% Downside - LBO Model'!$K$142)/-'5% Downside - LBO Model'!$F$191 -> 2.4081571
A6: 6% Base | B6: =('LBO Model'!$K$118*B$4*(1-'LBO Model'!$K$10)-'LBO Model'!$K$159+'LBO Model'!$K$142)/-'LBO Model'!$F$191 -> 2.1163112 | C6: =('LBO Model'!$K$118*C$4*(1-'LBO Model'!$K$10)-'LBO Model'!$K$159+'LBO Model'!$K$142)/-'LBO Model'!$F$191 -> 2.3149811 | D6: =('LBO Model'!$K$118*D$4*(1-'LBO Model'!$K$10)-'LBO Model'!$K$159+'LBO Model'!$K$142)/-'LBO Model'!$F$191 -> 2.5040904 | E6: =('LBO Model'!$K$118*E$4*(1-'LBO Model'!$K$10)-'LBO Model'!$K$159+'LBO Model'!$K$142)/-'LBO Model'!$F$191 -> 2.612986 | F6: =('LBO Model'!$K$118*F$4*(1-'LBO Model'!$K$10)-'LBO Model'!$K$159+'LBO Model'!$K$142)/-'LBO Model'!$F$191 -> 2.712321
A7: 7% Stretch | B7: =('7% Stretch - LBO Model'!$K$118*B$4*(1-'7% Stretch - LBO Model'!$K$10)-'7% Stretch - LBO Model'!$K$159+'7% Stretch - LBO Model'!$K$142)/-'7% Stretch - LBO Model'!$F$191 -> 2.2162431 | C7: =('7% Stretch - LBO Model'!$K$118*C$4*(1-'7% Stretch - LBO Model'!$K$10)-'7% Stretch - LBO Model'!$K$159+'7% Stretch - LBO Model'!$K$142)/-'7% Stretch - LBO Model'!$F$191 -> 2.4295413 | D7: =('7% Stretch - LBO Model'!$K$118*D$4*(1-'7% Stretch - LBO Model'!$K$10)-'7% Stretch - LBO Model'!$K$159+'7% Stretch - LBO Model'!$K$142)/-'7% Stretch - LBO Model'!$F$191 -> 2.6325749 | E7: =('7% Stretch - LBO Model'!$K$118*E$4*(1-'7% Stretch - LBO Model'!$K$10)-'7% Stretch - LBO Model'!$K$159+'7% Stretch - LBO Model'!$K$142)/-'7% Stretch - LBO Model'!$F$191 -> 2.7494886 | F7: =('7% Stretch - LBO Model'!$K$118*F$4*(1-'7% Stretch - LBO Model'!$K$10)-'7% Stretch - LBO Model'!$K$159+'7% Stretch - LBO Model'!$K$142)/-'7% Stretch - LBO Model'!$F$191 -> 2.8561377
A9: The 12.95x column holds the exit multiple at the modeled entry multiple; other columns show valuation sensitivity only.
A12: IRR Sensitivity | B12: 11 | C12: 12 | D12: 12.951877 | E12: 13.5 | F12: 14
A13: 5% Downside | B13: =B5^(1/5)-1 -> 0.13136614 | C13: =C5^(1/5)-1 -> 0.15308175 | D13: =D5^(1/5)-1 -> 0.17233454 | E13: =E5^(1/5)-1 -> 0.18287163 | F13: =F5^(1/5)-1 -> 0.19216664
A14: 6% Base | B14: =B6^(1/5)-1 -> 0.16175862 | C14: =C6^(1/5)-1 -> 0.18279503 | D14: =D6^(1/5)-1 -> 0.20151722 | E14: =E6^(1/5)-1 -> 0.21179015 | F14: =F6^(1/5)-1 -> 0.22086661
A15: 7% Stretch | B15: =B7^(1/5)-1 -> 0.1725287 | C15: =C7^(1/5)-1 -> 0.19427642 | D15: =D7^(1/5)-1 -> 0.21360162 | E15: =E7^(1/5)-1 -> 0.22419439 | F15: =F7^(1/5)-1 -> 0.23354736
A17: Five-year hold, no interim sponsor distributions. Sensitivity is illustrative and assumes other operating assumptions stay fixed.

Sheet Pitch Summary
A1: JBT Marel | Investment Pitch Summary
A2: Approval draft | 6% Base Case | Five-year illustrative buyout model | $ in millions unless noted
A4: The pitch in one minute
A5: Buy a global food-processing equipment and software platform whose machines are important to large food producers. Improve the combined JBT and Marel business by completing the already-announced cost-savings plan, applying AI-enabled vision and automation where it improves customers’ yield and labor productivity, and cross-selling a broader product line. The Base Case assumes 6% annual revenue growth, modest AI-related margin improvement, and debt paydown over five years. The case does not depend on acquiring more companies or expanding the exit valuation multiple.
A8: Why this company could matter
A9: What JBT Marel does | B9: Builds equipment, software and service systems used to process poultry, meat, fish, prepared foods and beverages.
A10: Why customers care | B10: A production-line outage or poor yield can cost a processor time and product. Integrated equipment, service, traceability and uptime are valuable in high-volume plants.
A11: Why people may care | B11: Consumers may not recognize the JBT Marel name, but food processors rely on its systems to help produce food at scale. The company is a behind-the-scenes food-supply-chain provider.
A12: Why it fits an LBO | B12: The merger creates a concrete integration and savings plan; the company reports recurring service revenue and meaningful free cash flow, supporting debt reduction.
A14: What the numbers mean and what the sponsor can influence
A15: Metric / assumption | B15: Plain-English meaning | C15: Case input / output | D15: What we can do or why it matters
A16: Revenue growth | B16: How quickly annual sales increase. | C16: 6% a year in Base; 5% downside; 7% stretch. | D16: Sell more integrated lines, cross-sell the combined product range, expand service and aftermarket sales. Only 5–7% through 2028 is company guidance; extending the rates through 2031 is our assumption.
A17: Adjusted EBITDA margin | B17: Operating profit before interest, taxes, depreciation and amortization as a share of sales. | C17: 20.0% FY2028 management target; Base rises to 20.5% by 2031 including AI uplift. | D17: Complete synergies, improve procurement and factory efficiency, and scale services/software.
A18: AI margin lift | B18: Extra EBITDA margin beyond the base plan attributed to AI-related product and operating improvements. | C18: Base: ramps to +0.50 percentage points by 2031; Stretch: +1.00 point. | D18: Analyst assumption, not management guidance or a reported company-wide AI saving. Track with measured pilot results before increasing it.
A19: Cash flow to debt paydown | B19: Cash generated after operations, interest, tax, working capital and capital spending that reduces acquisition debt. | C19: 70% of incremental EBITDA converted into debt paydown in the AI case. | D19: This is a modeling estimate, not a company promise. The full model also retains the template’s cash-flow and mandatory amortization mechanics.
A20: Entry EV / EBITDA | B20: Purchase price of the whole company divided by its annual operating profit. | C20: 12.95x in the model. | D20: Based on the illustrative entry price and EBITDA inputs in the model.
A21: Exit EV / EBITDA | B21: Sale price divided by EBITDA in the fifth year. | C21: ='LBO Model'!K9 -> 12.951877 | D21: No multiple expansion is required for the Base Case; keeping this flat is an assumption, not a prediction.
A22: MOIC | B22: Total sponsor proceeds divided by the sponsor’s initial investment. | C22: ='LBO Model'!C196 -> 2.5040904 | D22: A 2.0x MOIC means $2 back for every $1 invested, before considering timing.
A23: IRR | B23: Annualized return, accounting for the five-year hold. | C23: ='LBO Model'!C197 -> 0.20151722 | D23: A higher MOIC does not automatically mean a higher IRR if it takes longer to earn.
A25: Case | B25: Revenue growth | C25: 2031 EBITDA ($M) | D25: Sponsor return | E25: EBITDA margin | F25: Annualized IRR
A26: 5% Downside | B26: 0.05 | C26: ='5% Downside - LBO Model'!K118 -> 1028.0448 | D26: ='5% Downside - LBO Model'!C196 -> 2.2144089 | E26: ='5% Downside - LBO Model'!K119 -> 0.2 | F26: ='5% Downside - LBO Model'!C197 -> 0.17233454
A27: 6% Base | B27: 0.06 | C27: ='LBO Model'!K118 -> 1104.8892 | D27: ='LBO Model'!C196 -> 2.5040904 | E27: ='LBO Model'!K119 -> 0.205 | F27: ='LBO Model'!C197 -> 0.20151722
A28: 7% Stretch | B28: 0.07 | C28: ='7% Stretch - LBO Model'!K118 -> 1186.2432 | D28: ='7% Stretch - LBO Model'!C196 -> 2.6325749 | E28: ='7% Stretch - LBO Model'!K119 -> 0.21 | F28: ='7% Stretch - LBO Model'!C197 -> 0.21360162
A30: Company-reported savings plan and what the model does with it
A31: Reported milestone | B31: Company figure | C31: Model treatment / explanation | D31: How we would execute after acquisition
A32: FY2025 synergy savings realized | B32: $43M year-over-year | C32: Reported by JBT Marel; historical result. | D32: 1. Centralize duplicate purchasing, suppliers and selected corporate work while protecting customer service.
A33: Annualized savings exiting FY2025 | B33: $85M run-rate | C33: Company said this was achieved as it exited 2025. | D33: 2. Finish footprint and operating-process improvements already identified by management; measure cash restructuring costs against savings.
A34: FY2026 synergy savings expectation | B34: ~$60M in-year realized savings | C34: Management reaffirmed this expectation in its Q2 2026 release. | D34: 3. Cross-sell full production lines, aftermarket service and software through the combined global customer base.
A35: Annualized cost-synergy target exiting FY2027 | B35: $150M run-rate | C35: Management’s target; includes planned OPEX and COGS actions. It is not an additional $150M each year. | D35: 4. Expand machine-vision and AI features where trials prove better yield, less rework, higher uptime or less manual work.
A36: FY2025–FY2028 in-year synergy plan | B36: $43M; ~$60M; $30–40M; $10–15M | C36: Investor Day breakdown; model margin path already reflects the synergy plan, so savings are not separately added to EBITDA. | D36: 5. Use plant data and predictive maintenance to improve service response and prevent avoidable customer downtime; treat this as an opportunity to validate, not booked savings.
A37: Revenue synergies through FY2027 | B37: $75M cumulative target | C37: Separate from cost synergies; do not treat this as annual EBITDA or cost savings. | D37: 6. Reinvest only where customer payback is measurable; direct available cash to debt reduction under the LBO plan.
A39: AI evidence and what it does (and does not) prove
A40: Evidence | B40: What it supports | C40: Limit / how to use it in the pitch
A41: ATHENA poultry deboning case: machine-learning vision is used to adapt deboning to each product. | B41: JBT Marel’s Investor Day reports >60% lower labor requirements for loading, harvesting and trimming in one customer application. | C41: This is a specific customer case, not a company-wide labor reduction or JBT Marel margin improvement.
A42: Company AI article describes task-specific vision models deployed in machine software. | B42: AI can identify features and improve consistency; JBT Marel says reusable models can reduce engineering hours. | C42: The company says it applies AI selectively; it does not say every machine uses AI.
A43: Customer benefit can include higher yield, less trimming/rework, consistent quality and throughput. | B43: A stronger value proposition may support new equipment wins, upgrades, service attachment and customer retention. | C43: Incremental revenue and EBITDA from these effects have not been quantified in company guidance.
A44: Analyst case assumes 0.5-point incremental EBITDA-margin benefit by 2031 in Base. | B44: A transparent upside test for the LBO model. | C44: Keep separate from the confirmed $150M merger savings plan; do not double count.
A46: Main risks and honest pitch framing
A47: Integration risk | B47: Synergies may arrive later, cost more, or be offset by cost inflation and tariffs.
A48: Growth risk | B48: 2025 growth includes the merger and FY2026 guidance includes FX; 6% for five forecast years is not guaranteed.
...
